2025-07-11 08:44:54,797 - INFO - --- FASE 1: SETUP ---
2025-07-11 08:44:54,952 - INFO - Workspace creato: c29a8457-ac4a-4a97-a0ec-a94c55f5eac3
2025-07-11 08:44:55,199 - INFO - Goal creato con successo.
2025-07-11 08:44:55,199 - INFO - 
--- FASE 2: TRIGGER AUTONOMOUS FLOW ---
2025-07-11 08:45:09,011 - INFO - Proposta di team creata: 39675470-bfbc-44a8-9873-f34b5a4a4137
2025-07-11 08:45:19,017 - ERROR - 
❌❌❌ Extended E2E Test FAILED: HTTPConnectionPool(host='localhost', port=8000): Read timed out. (read timeout=10) ❌❌❌
Traceback (most recent call last):
  File "/opt/homebrew/lib/python3.13/site-packages/urllib3/connectionpool.py", line 534, in _make_request
    response = conn.getresponse()
  File "/opt/homebrew/lib/python3.13/site-packages/urllib3/connection.py", line 565, in getresponse
    httplib_response = super().getresponse()
  File "/opt/homebrew/Cellar/python@3.13/3.13.3/Frameworks/Python.framework/Versions/3.13/lib/python3.13/http/client.py", line 1430, in getresponse
    response.begin()
    ~~~~~~~~~~~~~~^^
  File "/opt/homebrew/Cellar/python@3.13/3.13.3/Frameworks/Python.framework/Versions/3.13/lib/python3.13/http/client.py", line 331, in begin
    version, status, reason = self._read_status()
                              ~~~~~~~~~~~~~~~~~^^
  File "/opt/homebrew/Cellar/python@3.13/3.13.3/Frameworks/Python.framework/Versions/3.13/lib/python3.13/http/client.py", line 292, in _read_status
    line = str(self.fp.readline(_MAXLINE + 1), "iso-8859-1")
               ~~~~~~~~~~~~~~~~^^^^^^^^^^^^^^
  File "/opt/homebrew/Cellar/python@3.13/3.13.3/Frameworks/Python.framework/Versions/3.13/lib/python3.13/socket.py", line 719, in readinto
    return self._sock.recv_into(b)
           ~~~~~~~~~~~~~~~~~~~~^^^
TimeoutError: timed out

The above exception was the direct cause of the following exception:

Traceback (most recent call last):
  File "/opt/homebrew/lib/python3.13/site-packages/requests/adapters.py", line 667, in send
    resp = conn.urlopen(
        method=request.method,
    ...<9 lines>...
        chunked=chunked,
    )
  File "/opt/homebrew/lib/python3.13/site-packages/urllib3/connectionpool.py", line 841, in urlopen
    retries = retries.increment(
        method, url, error=new_e, _pool=self, _stacktrace=sys.exc_info()[2]
    )
  File "/opt/homebrew/lib/python3.13/site-packages/urllib3/util/retry.py", line 474, in increment
    raise reraise(type(error), error, _stacktrace)
          ~~~~~~~^^^^^^^^^^^^^^^^^^^^^^^^^^^^^^^^^
  File "/opt/homebrew/lib/python3.13/site-packages/urllib3/util/util.py", line 39, in reraise
    raise value
  File "/opt/homebrew/lib/python3.13/site-packages/urllib3/connectionpool.py", line 787, in urlopen
    response = self._make_request(
        conn,
    ...<10 lines>...
        **response_kw,
    )
  File "/opt/homebrew/lib/python3.13/site-packages/urllib3/connectionpool.py", line 536, in _make_request
    self._raise_timeout(err=e, url=url, timeout_value=read_timeout)
    ~~~~~~~~~~~~~~~~~~~^^^^^^^^^^^^^^^^^^^^^^^^^^^^^^^^^^^^^^^^^^^^
  File "/opt/homebrew/lib/python3.13/site-packages/urllib3/connectionpool.py", line 367, in _raise_timeout
    raise ReadTimeoutError(
        self, url, f"Read timed out. (read timeout={timeout_value})"
    ) from err
urllib3.exceptions.ReadTimeoutError: HTTPConnectionPool(host='localhost', port=8000): Read timed out. (read timeout=10)

During handling of the above exception, another exception occurred:

Traceback (most recent call last):
  File "/Users/pelleri/Documents/ai-team-orchestrator/backend/extended_autonomous_test.py", line 36, in run_extended_e2e_test
    _trigger_and_approve_proposal(workspace_id)
    ~~~~~~~~~~~~~~~~~~~~~~~~~~~~~^^^^^^^^^^^^^^
  File "/Users/pelleri/Documents/ai-team-orchestrator/backend/extended_autonomous_test.py", line 99, in _trigger_and_approve_proposal
    approval_response = requests.post(f"{BASE_URL}/api/director/approve/{workspace_id}", params={"proposal_id": proposal_id}, timeout=10)
  File "/opt/homebrew/lib/python3.13/site-packages/requests/api.py", line 115, in post
    return request("post", url, data=data, json=json, **kwargs)
  File "/opt/homebrew/lib/python3.13/site-packages/requests/api.py", line 59, in request
    return session.request(method=method, url=url, **kwargs)
           ~~~~~~~~~~~~~~~^^^^^^^^^^^^^^^^^^^^^^^^^^^^^^^^^^
  File "/opt/homebrew/lib/python3.13/site-packages/requests/sessions.py", line 589, in request
    resp = self.send(prep, **send_kwargs)
  File "/opt/homebrew/lib/python3.13/site-packages/requests/sessions.py", line 703, in send
    r = adapter.send(request, **kwargs)
  File "/opt/homebrew/lib/python3.13/site-packages/requests/adapters.py", line 713, in send
    raise ReadTimeout(e, request=request)
requests.exceptions.ReadTimeout: HTTPConnectionPool(host='localhost', port=8000): Read timed out. (read timeout=10)
2025-07-11 08:45:19,035 - INFO - 
--- FASE 5: CLEANUP ---
2025-07-11 08:45:21,446 - INFO - Cleanup response: 200
