/opt/homebrew/lib/python3.13/site-packages/pydantic/_internal/_config.py:373: UserWarning: Valid config keys have changed in V2:
* 'allow_population_by_field_name' has been renamed to 'validate_by_name'
  warnings.warn(message, UserWarning)
AI Quality Assurance system not fully available: cannot import name 'AIQualityEvaluator' from 'ai_quality_assurance.unified_quality_engine' (/Users/pelleri/Documents/ai-team-orchestrator/backend/ai_quality_assurance/unified_quality_engine.py)
ðŸ”§ ENHANCED TASK EXECUTOR CONFIGURATION
auto_generation_enabled: True
analysis_enabled: True
Traceback (most recent call last):
  File "/Users/pelleri/Documents/ai-team-orchestrator/backend/main.py", line 42, in <module>
    from routes.ai_content_processor import router as ai_content_router
  File "/Users/pelleri/Documents/ai-team-orchestrator/backend/routes/ai_content_processor.py", line 393
    processed_content = re.sub(explanation_pattern, '', processed_content, flags=re.DOTALL)
IndentationError: unexpected indent
